<?xml version="1.0" ?>
<!-- =================================================================================== -->
<!-- |    This document was autogenerated by xacro from robot.xacro                    | -->
<!-- |    EDITING THIS FILE BY HAND IS NOT RECOMMENDED                                 | -->
<!-- =================================================================================== -->
<robot name="robot">
  <material name="silver">
    <color rgba="0.700 0.700 0.700 1.000"/>
  </material>
  <material name="purple">
    <color rgba="0.19 0.11 0.57 1.000"/>
  </material>
  <material name="black">
    <color rgba="0.0 0.0 0.0 1.000"/>
  </material>
  <gazebo>
    <plugin filename="libgazebo_ros_control.so" name="control"/>
  </gazebo>
  <gazebo reference="base_link">
    <material>Gazebo/Grey</material>
    <mu1>0.2</mu1>
    <mu2>0.2</mu2>
    <self_collide>true</self_collide>
    <gravity>true</gravity>
  </gazebo>
  <gazebo reference="left_wheel_1">
    <material>Gazebo/Black</material>
    <mu1>0.2</mu1>
    <mu2>0.2</mu2>
    <self_collide>true</self_collide>
  </gazebo>
  <gazebo reference="left_wheel__1__1">
    <material>Gazebo/Black</material>
    <mu1>0.2</mu1>
    <mu2>0.2</mu2>
    <self_collide>true</self_collide>
  </gazebo>
  <gazebo reference="right_wheel_1">
    <material>Gazebo/Black</material>
    <mu1>0.2</mu1>
    <mu2>0.2</mu2>
    <self_collide>true</self_collide>
  </gazebo>
  <gazebo reference="right_wheel__1__1">
    <material>Gazebo/Black</material>
    <mu1>0.2</mu1>
    <mu2>0.2</mu2>
    <self_collide>true</self_collide>
  </gazebo>
  <gazebo reference="camera_1">
    <material>Gazebo/SkyBlue</material>
    <mu1>0.2</mu1>
    <mu2>0.2</mu2>
    <self_collide>true</self_collide>
    <sensor name="camera_sensor" type="camera">
      <pose>0 0 0 0 0 0</pose>
      <visualize>true</visualize>
      <update_rate>30</update_rate>
      <camera>
        <horizontal_fov>1.047</horizontal_fov>
        <image>
          <width>640</width>
          <height>480</height>
          <format>R8G8B8</format>
        </image>
        <clip>
          <near>0.1</near>
          <far>100</far>
        </clip>
      </camera>
      <plugin filename="libgazebo_ros_camera.so" name="gazebo_ros_camera">
        <ros>
          <namespace/>
          <remapping>image_raw:=/camera/image_raw</remapping>
        </ros>
        <frameName>camera_link</frameName>
      </plugin>
    </sensor>
  </gazebo>
  <gazebo reference="lidar_1">
    <material>Gazebo/Black</material>
    <mu1>0.2</mu1>
    <mu2>0.2</mu2>
    <self_collide>true</self_collide>
    <sensor name="ydlidar" type="ray">
      <always_on>true</always_on>
      <visualize>false</visualize>
      <update_rate>10</update_rate>
      <ray>
        <scan>
          <horizontal>
            <samples>720</samples>
            <resolution>1.000000</resolution>
            <min_angle>-3.14</min_angle>
            <max_angle>3.14</max_angle>
          </horizontal>
        </scan>
        <range>
          <min>0.05</min>
          <max>20.0</max>
          <resolution>0.015000</resolution>
        </range>
        <noise>
          <type>gaussian</type>
          <mean>0.0</mean>
          <stddev>0.01</stddev>
        </noise>
      </ray>
      <plugin filename="libgazebo_ros_ray_sensor.so" name="scan">
        <ros>
          <remapping>~/out:=scan</remapping>
        </ros>
        <output_type>sensor_msgs/LaserScan</output_type>
        <frame_name>lidar_1</frame_name>
      </plugin>
    </sensor>
  </gazebo>
  <!-- Differential Drive Plugin -->
  <gazebo>
    <plugin filename="libgazebo_ros_diff_drive.so" name="wheel_drive_controller">
      <!-- wheels -->
      <num_wheel_pairs>1</num_wheel_pairs>
      <left_joint>Revolute 1</left_joint>
      <right_joint>Revolute 3</right_joint>
      <!-- kinematics -->
      <wheel_separation>0.12</wheel_separation>
      <wheel_diameter>0.08</wheel_diameter>
      <max_wheel_torque>20.0</max_wheel_torque>
      <max_wheel_acceleration>1.0</max_wheel_acceleration>
      <!-- odometry  -->
      <odometry_source>1</odometry_source>
      <odometry_frame>odom</odometry_frame>
      <robot_base_frame>base_link</robot_base_frame>
      <!-- topic & re remappings -->
      <ros>
        <namespace>/</namespace>
        <remapping>/cmd_vel:=cmd_vel</remapping>
        <remapping>/odom:=odom</remapping>
      </ros>
      <publish_odom>true</publish_odom>
      <publish_odom_tf>true</publish_odom_tf>
      <publish_wheel_tf>false</publish_wheel_tf>
      <update_rate>100.0</update_rate>
    </plugin>
  </gazebo>
  <link name="base_link">
    <inertial>
      <origin rpy="0 0 0" xyz="0.005833719964014702 0.0 0.06433887018887323"/>
      <mass value="0.8022984225987435"/>
      <inertia ixx="0.001476" ixy="0.0" ixz="-0.000103" iyy="0.003076" iyz="-0.0" izz="0.003929"/>
    </inertial>
    <visual>
      <origin rpy="0 0 0" xyz="0 0 0"/>
      <geometry>
        <mesh filename="file:///home/yash/ros_ws/install/robot_description/share/robot_description/models/meshes/base_link.stl" scale="0.001 0.001 0.001"/>
      </geometry>
      <material name="silver"/>
    </visual>
    <collision>
      <origin rpy="0 0 0" xyz="0 0 0"/>
      <geometry>
        <mesh filename="file:///home/yash/ros_ws/install/robot_description/share/robot_description/models/meshes/base_link.stl" scale="0.001 0.001 0.001"/>
      </geometry>
    </collision>
  </link>
  <link name="left_wheel_1">
    <inertial>
      <origin rpy="0 0 0" xyz="2.699229728619912e-15 -0.012500000000000011 2.8449465006019636e-16"/>
      <mass value="0.6456689578951122"/>
      <inertia ixx="0.000206" ixy="-0.0" ixz="0.0" iyy="0.000344" iyz="-0.0" izz="0.000206"/>
    </inertial>
    <visual>
      <origin rpy="0 0 0" xyz="-0.06 -0.078 -0.0325"/>
      <geometry>
        <mesh filename="file:///home/yash/ros_ws/install/robot_description/share/robot_description/models/meshes/left_wheel_1.stl" scale="0.001 0.001 0.001"/>
      </geometry>
      <material name="black"/>
    </visual>
    <collision>
      <origin rpy="0 0 0" xyz="-0.06 -0.078 -0.0325"/>
      <geometry>
        <mesh filename="file:///home/yash/ros_ws/install/robot_description/share/robot_description/models/meshes/left_wheel_1.stl" scale="0.001 0.001 0.001"/>
      </geometry>
    </collision>
  </link>
  <link name="left_wheel__1__1">
    <inertial>
      <origin rpy="0 0 0" xyz="2.67841304690819e-15 -0.012500000000000011 4.163336342344337e-17"/>
      <mass value="0.6456689578951122"/>
      <inertia ixx="0.000206" ixy="0.0" ixz="-0.0" iyy="0.000344" iyz="0.0" izz="0.000206"/>
    </inertial>
    <visual>
      <origin rpy="0 0 0" xyz="0.06 -0.078 -0.0325"/>
      <geometry>
        <mesh filename="file:///home/yash/ros_ws/install/robot_description/share/robot_description/models/meshes/left_wheel__1__1.stl" scale="0.001 0.001 0.001"/>
      </geometry>
      <material name="black"/>
    </visual>
    <collision>
      <origin rpy="0 0 0" xyz="0.06 -0.078 -0.0325"/>
      <geometry>
        <mesh filename="file:///home/yash/ros_ws/install/robot_description/share/robot_description/models/meshes/left_wheel__1__1.stl" scale="0.001 0.001 0.001"/>
      </geometry>
    </collision>
  </link>
  <link name="right_wheel_1">
    <inertial>
      <origin rpy="0 0 0" xyz="2.6853519408120974e-15 0.012499999999999997 2.1510571102112408e-16"/>
      <mass value="0.6456689578951125"/>
      <inertia ixx="0.000206" ixy="0.0" ixz="-0.0" iyy="0.000344" iyz="-0.0" izz="0.000206"/>
    </inertial>
    <visual>
      <origin rpy="0 0 0" xyz="-0.06 0.078 -0.0325"/>
      <geometry>
        <mesh filename="file:///home/yash/ros_ws/install/robot_description/share/robot_description/models/meshes/right_wheel_1.stl" scale="0.001 0.001 0.001"/>
      </geometry>
      <material name="black"/>
    </visual>
    <collision>
      <origin rpy="0 0 0" xyz="-0.06 0.078 -0.0325"/>
      <geometry>
        <mesh filename="file:///home/yash/ros_ws/install/robot_description/share/robot_description/models/meshes/right_wheel_1.stl" scale="0.001 0.001 0.001"/>
      </geometry>
    </collision>
  </link>
  <link name="right_wheel__1__1">
    <inertial>
      <origin rpy="0 0 0" xyz="2.7131075164277263e-15 0.012499999999999997 1.3877787807814457e-17"/>
      <mass value="0.6456689578951125"/>
      <inertia ixx="0.000206" ixy="0.0" ixz="-0.0" iyy="0.000344" iyz="0.0" izz="0.000206"/>
    </inertial>
    <visual>
      <origin rpy="0 0 0" xyz="0.06 0.078 -0.0325"/>
      <geometry>
        <mesh filename="file:///home/yash/ros_ws/install/robot_description/share/robot_description/models/meshes/right_wheel__1__1.stl" scale="0.001 0.001 0.001"/>
      </geometry>
      <material name="black"/>
    </visual>
    <collision>
      <origin rpy="0 0 0" xyz="0.06 0.078 -0.0325"/>
      <geometry>
        <mesh filename="file:///home/yash/ros_ws/install/robot_description/share/robot_description/models/meshes/right_wheel__1__1.stl" scale="0.001 0.001 0.001"/>
      </geometry>
    </collision>
  </link>
  <link name="camera_1">
    <inertial>
      <origin rpy="0 0 0" xyz="0.001999999999999974 0.0 -5.228456556594097e-13"/>
      <mass value="0.0024661502330680955"/>
      <inertia ixx="0.0" ixy="0.0" ixz="-0.0" iyy="0.0" iyz="0.0" izz="0.0"/>
    </inertial>
    <visual>
      <origin rpy="0 0 0" xyz="-0.1 -0.0 -0.07964"/>
      <geometry>
        <mesh filename="file:///home/yash/ros_ws/install/robot_description/share/robot_description/models/meshes/camera_1.stl" scale="0.001 0.001 0.001"/>
      </geometry>
      <material name="purple"/>
    </visual>
    <collision>
      <origin rpy="0 0 0" xyz="-0.1 -0.0 -0.07964"/>
      <geometry>
        <mesh filename="file:///home/yash/ros_ws/install/robot_description/share/robot_description/models/meshes/camera_1.stl" scale="0.001 0.001 0.001"/>
      </geometry>
    </collision>
  </link>
  <link name="lidar_1">
    <inertial>
      <origin rpy="0 0 0" xyz="0.0 -5.026061718855926e-18 0.0050000000000000044"/>
      <mass value="0.05548838024402973"/>
      <inertia ixx="4e-06" ixy="-0.0" ixz="0.0" iyy="4e-06" iyz="0.0" izz="6e-06"/>
    </inertial>
    <visual>
      <origin rpy="0 0 0" xyz="-0.0 -0.0 -0.1095"/>
      <geometry>
        <mesh filename="file:///home/yash/ros_ws/install/robot_description/share/robot_description/models/meshes/lidar_1.stl" scale="0.001 0.001 0.001"/>
      </geometry>
      <material name="black"/>
    </visual>
    <collision>
      <origin rpy="0 0 0" xyz="-0.0 -0.0 -0.1095"/>
      <geometry>
        <mesh filename="file:///home/yash/ros_ws/install/robot_description/share/robot_description/models/meshes/lidar_1.stl" scale="0.001 0.001 0.001"/>
      </geometry>
    </collision>
  </link>
  <joint name="Revolute 1" type="continuous">
    <origin rpy="0 0 0" xyz="0.06 0.078 0.0325"/>
    <parent link="base_link"/>
    <child link="left_wheel_1"/>
    <axis xyz="0.0 1.0 0.0"/>
    <limit effort="100" lower="0.0" upper="6.283185" velocity="100"/>
  </joint>
  <joint name="Revolute 2" type="continuous">
    <origin rpy="0 0 0" xyz="-0.06 0.078 0.0325"/>
    <parent link="base_link"/>
    <child link="left_wheel__1__1"/>
    <axis xyz="0.0 1.0 0.0"/>
    <limit effort="100" lower="0.0" upper="6.283185" velocity="100"/>
  </joint>
  <joint name="Revolute 3" type="continuous">
    <origin rpy="0 0 0" xyz="0.06 -0.078 0.0325"/>
    <parent link="base_link"/>
    <child link="right_wheel_1"/>
    <axis xyz="0.0 1.0 0.0"/>
    <limit effort="100" lower="0.0" upper="6.283185" velocity="100"/>
  </joint>
  <joint name="Revolute 4" type="continuous">
    <origin rpy="0 0 0" xyz="-0.06 -0.078 0.0325"/>
    <parent link="base_link"/>
    <child link="right_wheel__1__1"/>
    <axis xyz="0.0 -1.0 0.0"/>
    <limit effort="100" lower="0.0" upper="6.283185" velocity="100"/>
  </joint>
  <joint name="Rigid 5" type="fixed">
    <origin rpy="0 0 0" xyz="0.1 0.0 0.07964"/>
    <parent link="base_link"/>
    <child link="camera_1"/>
  </joint>
  <joint name="Revolute 6" type="fixed">
    <origin rpy="0 0 0" xyz="0.0 0.0 0.1095"/>
    <parent link="base_link"/>
    <child link="lidar_1"/>
    <axis xyz="0.0 0.0 1.0"/>
    <limit effort="100" lower="0.0" upper="6.283185" velocity="100"/>
  </joint>
</robot>
